<?xml version="1.0" ?>
<robot name="URDF_finger_ssss" xmlns:xacro="http://www.ros.org/wiki/xacro">

<link name="base_link">
  <inertial>
    <origin xyz="5.810609836920757e-14 -3.5557377263056094e-06 0.004698273696031688" rpy="0 0 0"/>
    <mass value="0.004531103214243681"/>
    <inertia ixx="0.0" iyy="0.0" izz="0.0" ixy="-0.0" iyz="-0.0" ixz="-0.0"/>
  </inertial>
  <visual>
    <origin xyz="0 0 0" rpy="0 0 0"/>
    <geometry>
      <mesh filename="package://shortest/meshes/base_link.stl" scale="0.001 0.001 0.001"/>
    </geometry>
    <material name="silver">
        <color rgba="0.7 0.7 0.7 1"/>
      </material>
  </visual>
  <collision>
    <origin xyz="0 0 0" rpy="0 0 0"/>
    <geometry>
      <mesh filename="package://shortest/meshes/base_link.stl" scale="0.001 0.001 0.001"/>
    </geometry>
  </collision>
</link>

<link name="MCP_spread_motor_1">
  <inertial>
    <origin xyz="4.40257654920099e-06 -0.0075382982459979535 -0.011349379478781948" rpy="0 0 0"/>
    <mass value="0.11379089624899982"/>
    <inertia ixx="1.6e-05" iyy="8e-06" izz="1.5e-05" ixy="0.0" iyz="0.0" ixz="-0.0"/>
  </inertial>
  <visual>
    <origin xyz="-0.0 0.0 -0.0036" rpy="0 0 0"/>
    <geometry>
      <mesh filename="package://shortest/meshes/MCP_spread_motor_1.stl" scale="0.001 0.001 0.001"/>
    </geometry>
    <material name="silver">
        <color rgba="0.7 0.7 0.7 1"/>
      </material>
  </visual>
  <collision>
    <origin xyz="-0.0 0.0 -0.0036" rpy="0 0 0"/>
    <geometry>
      <mesh filename="package://shortest/meshes/MCP_spread_motor_1.stl" scale="0.001 0.001 0.001"/>
    </geometry>
  </collision>
</link>

<link name="MCP_motor_1">
  <inertial>
    <origin xyz="-0.011349379464972085 0.0075382982462910975 4.402565036953562e-06" rpy="0 0 0"/>
    <mass value="0.11379089638693088"/>
    <inertia ixx="1.5e-05" iyy="8e-06" izz="1.6e-05" ixy="-0.0" iyz="-0.0" ixz="-0.0"/>
  </inertial>
  <visual>
    <origin xyz="-0.0106 -0.0235 0.008" rpy="0 0 0"/>
    <geometry>
      <mesh filename="package://shortest/meshes/MCP_motor_1.stl" scale="0.001 0.001 0.001"/>
    </geometry>
    <material name="silver">
        <color rgba="0.7 0.7 0.7 1"/>
      </material>
  </visual>
  <collision>
    <origin xyz="-0.0106 -0.0235 0.008" rpy="0 0 0"/>
    <geometry>
      <mesh filename="package://shortest/meshes/MCP_motor_1.stl" scale="0.001 0.001 0.001"/>
    </geometry>
  </collision>
</link>

<link name="proximal_1">
  <inertial>
    <origin xyz="-0.007236862961978075 0.027666892539839255 -4.565792188770956e-15" rpy="0 0 0"/>
    <mass value="0.03768293771588789"/>
    <inertia ixx="5e-06" iyy="8e-06" izz="1.1e-05" ixy="0.0" iyz="-0.0" ixz="-0.0"/>
  </inertial>
  <visual>
    <origin xyz="-0.0105 -0.0235 0.008" rpy="0 0 0"/>
    <geometry>
      <mesh filename="package://shortest/meshes/proximal_1.stl" scale="0.001 0.001 0.001"/>
    </geometry>
    <material name="silver">
        <color rgba="0.7 0.7 0.7 1"/>
      </material>
  </visual>
  <collision>
    <origin xyz="-0.0105 -0.0235 0.008" rpy="0 0 0"/>
    <geometry>
      <mesh filename="package://shortest/meshes/proximal_1.stl" scale="0.001 0.001 0.001"/>
    </geometry>
  </collision>
</link>

<link name="PIP_DIP_motor_1">
  <inertial>
    <origin xyz="-0.011349379464972083 0.007538298246842587 4.402565036979583e-06" rpy="0 0 0"/>
    <mass value="0.11379089638693098"/>
    <inertia ixx="1.5e-05" iyy="8e-06" izz="1.6e-05" ixy="-0.0" iyz="-0.0" ixz="-0.0"/>
  </inertial>
  <visual>
    <origin xyz="-0.0106 -0.0625 0.008" rpy="0 0 0"/>
    <geometry>
      <mesh filename="package://shortest/meshes/PIP_DIP_motor_1.stl" scale="0.001 0.001 0.001"/>
    </geometry>
    <material name="silver">
        <color rgba="0.7 0.7 0.7 1"/>
      </material>
  </visual>
  <collision>
    <origin xyz="-0.0106 -0.0625 0.008" rpy="0 0 0"/>
    <geometry>
      <mesh filename="package://shortest/meshes/PIP_DIP_motor_1.stl" scale="0.001 0.001 0.001"/>
    </geometry>
  </collision>
</link>

<link name="middle_1">
  <inertial>
    <origin xyz="-0.007884360620471112 0.022545172845046313 0.0" rpy="0 0 0"/>
    <mass value="0.026746234501644296"/>
    <inertia ixx="2e-06" iyy="6e-06" izz="7e-06" ixy="0.0" iyz="0.0" ixz="-0.0"/>
  </inertial>
  <visual>
    <origin xyz="-0.0105 -0.0625 0.008" rpy="0 0 0"/>
    <geometry>
      <mesh filename="package://shortest/meshes/middle_1.stl" scale="0.001 0.001 0.001"/>
    </geometry>
    <material name="silver">
        <color rgba="0.7 0.7 0.7 1"/>
      </material>
  </visual>
  <collision>
    <origin xyz="-0.0105 -0.0625 0.008" rpy="0 0 0"/>
    <geometry>
      <mesh filename="package://shortest/meshes/middle_1.stl" scale="0.001 0.001 0.001"/>
    </geometry>
  </collision>
</link>

<link name="distal_1">
  <inertial>
    <origin xyz="-0.013500000000000002 0.016749645936636748 3.469446951953614e-18" rpy="0 0 0"/>
    <mass value="0.11248722366134255"/>
    <inertia ixx="1.7e-05" iyy="8e-06" izz="1.8e-05" ixy="0.0" iyz="0.0" ixz="-0.0"/>
  </inertial>
  <visual>
    <origin xyz="-0.0135 -0.093 0.008" rpy="0 0 0"/>
    <geometry>
      <mesh filename="package://shortest/meshes/distal_1.stl" scale="0.001 0.001 0.001"/>
    </geometry>
    <material name="silver">
        <color rgba="0.7 0.7 0.7 1"/>
      </material>
  </visual>
  <collision>
    <origin xyz="-0.0135 -0.093 0.008" rpy="0 0 0"/>
    <geometry>
      <mesh filename="package://shortest/meshes/distal_1.stl" scale="0.001 0.001 0.001"/>
    </geometry>
  </collision>
</link>

<link name="metacarpal_1">
  <inertial>
    <origin xyz="0.000507870018372718 -0.0021674150680712355 -0.011500000000001617" rpy="0 0 0"/>
    <mass value="0.1043693930100677"/>
    <inertia ixx="2.6e-05" iyy="2.4e-05" izz="4e-05" ixy="-1e-06" iyz="-0.0" ixz="-0.0"/>
  </inertial>
  <visual>
    <origin xyz="-0.0 -0.0 -0.0035" rpy="0 0 0"/>
    <geometry>
      <mesh filename="package://shortest/meshes/metacarpal_1.stl" scale="0.001 0.001 0.001"/>
    </geometry>
    <material name="silver">
        <color rgba="0.7 0.7 0.7 1"/>
      </material>
  </visual>
  <collision>
    <origin xyz="-0.0 -0.0 -0.0035" rpy="0 0 0"/>
    <geometry>
      <mesh filename="package://shortest/meshes/metacarpal_1.stl" scale="0.001 0.001 0.001"/>
    </geometry>
  </collision>
</link>

<joint name="MCP_spread" type="continuous">
  <origin xyz="0.0 0.0 0.0036" rpy="0 0 0"/>
  <parent link="base_link"/>
  <child link="MCP_spread_motor_1"/>
  <axis xyz="0.0 0.0 -1.0"/>
</joint>

<joint name="MCP" type="continuous">
  <origin xyz="0.0106 0.0235 -0.0115" rpy="0 0 0"/>
  <parent link="metacarpal_1"/>
  <child link="MCP_motor_1"/>
  <axis xyz="-1.0 -0.0 -0.0"/>
</joint>

<joint name="Proximal_to_motor" type="fixed">
  <origin xyz="-0.0001 0.0 0.0" rpy="0 0 0"/>
  <parent link="MCP_motor_1"/>
  <child link="proximal_1"/>
</joint>

<joint name="PIP" type="continuous">
  <origin xyz="0.0001 0.039 0.0" rpy="0 0 0"/>
  <parent link="proximal_1"/>
  <child link="PIP_DIP_motor_1"/>
  <axis xyz="-1.0 -0.0 0.0"/>
</joint>

<joint name="Middle_to_motor" type="fixed">
  <origin xyz="-0.0001 0.0 0.0" rpy="0 0 0"/>
  <parent link="PIP_DIP_motor_1"/>
  <child link="middle_1"/>
</joint>

<joint name="DIP" type="continuous">
  <origin xyz="0.003 0.0305 0.0" rpy="0 0 0"/>
  <parent link="middle_1"/>
  <child link="distal_1"/>
  <axis xyz="1.0 0.0 -0.0"/>
</joint>

<joint name="Metacarpal_to_motor" type="fixed">
  <origin xyz="0.0 0.0 -0.0001" rpy="0 0 0"/>
  <parent link="MCP_spread_motor_1"/>
  <child link="metacarpal_1"/>
</joint>

</robot>
