<mujoco model="iiwa7">
  <compiler angle="radian" meshdir="/home/loic/Downloads/crawling_hand-main/single_finger/longest/meshes/" autolimits="true"/>
  <size njmax="500" nconmax="200"/>
  <statistic meansize="0.0450074" extent="2" center="0 0 0"/>
  <default class="main">
    <joint limited="true" damping="0.01"/>
    <geom solimp="0.8 0.8 0.01 0.5 2" margin="0.001" material="geom" rgba="0.8 0.6 0.4 1"/>
    <site rgba="1 0 0 0.5"/>
    <default class="visual">
      <geom contype="0" conaffinity="0"/>
    </default>
    <default class="collision">
      <geom friction="1 0.5 0.1"/>
    </default>
    <default class="obj">
      <geom condim="6" friction="1 0.5 0.1"/>
    </default>
    <default class="fingers">
      <geom friction="1 0.5 0.2"/>
    </default>
    <default class="visual1"/>
    <default class="visual2"/>
    <default class="visual3"/>
    <default class="visual4"/>
    <default class="visual5"/>
  </default>
  <asset>
    <texture type="cube" name="texgeom" builtin="flat" mark="cross" rgb1="0.8 0.6 0.4" rgb2="0.8 0.6 0.4" markrgb="1 1 1" width="127" height="762"/>
    <texture type="2d" name="texplane" builtin="checker" rgb1="0.2 0.3 0.4" rgb2="0.1 0.15 0.2" width="512" height="512"/>
    <texture type="cube" name="allegro_mount_tex" builtin="flat" rgb1="0.2 0.2 0.2" width="32" height="192"/>
    <texture type="cube" name="hand_tex" builtin="flat" rgb1="0.2 0.2 0.2" width="32" height="192"/>
    <texture type="cube" name="tip_tex" builtin="flat" rgb1="0.9 0.9 0.9" width="32" height="192"/>
    <material name="MatPlane" texture="texplane" texuniform="true" reflectance="0.5"/>
    <material name="geom" texture="texgeom" texuniform="true"/>
    <material name="allegro_mount_mat" specular="0.25" shininess="0.03"/>
    <material name="hand_mat" specular="0.25" shininess="0.03"/>
    <material name="tip_mat" specular="0.25" shininess="0.03"/>
    <mesh name="base_link" file="base_link.stl" scale="0.001 0.001 0.001"/>
    <mesh name="MCP_spread_motor_1" file="MCP_spread_motor_1.stl" scale="0.001 0.001 0.001"/>
    <mesh name="MCP_motor_1" file="MCP_motor_1.stl" scale="0.001 0.001 0.001"/>
    <mesh name="proximal_1" file="proximal_1.stl" scale="0.001 0.001 0.001"/>
    <mesh name="PIP_DIP_motor_1" file="PIP_DIP_motor_1.stl" scale="0.001 0.001 0.001"/>
    <mesh name="middle_1" file="middle_1.stl" scale="0.001 0.001 0.001"/>
    <mesh name="distal_1" file="distal_1.stl" scale="0.001 0.001 0.001"/>
    <mesh name="metacarpal_1" file="metacarpal_1.stl" scale="0.001 0.001 0.001"/>
  </asset>
  <worldbody>
    <geom name="floor" class="collision" size="10 10 1" type="plane" material="MatPlane" rgba="0.8 0.8 0.8 1"/>
    <light pos="0 0 10" dir="0 0 -1" castshadow="false"/>
    <light pos="0 0 4" dir="0 -0.14834 -0.988936" diffuse="0.8 0.8 0.8"/>
    <body name="hand" pos="0 0 0.01">
      <joint limited="false" type="free" damping="0"/>
      <geom name="hand_base" class="fingers" size="0.08 0.08 0.01" type="box" rgba="0.1 1 0.1 1"/>
      <body name="finger_1" pos="0 0.11 0.006">
        <geom size="0.015 0.02 0.002" pos="0 -0.01 0.007" type="box" rgba="0.1 1 0.1 1"/>
        <geom type="mesh" rgba="0.7 0.7 0.7 1" mesh="base_link"/>
        <body name="MCP_spread_motor_1" pos="0 0 0.0036">
          <joint name="MCP_spread_1" pos="0 0 0" axis="0 0 -1" range="-2 2"/>
          <geom pos="0 0 -0.0036" type="mesh" rgba="0.7 0.7 0.7 1" mesh="MCP_spread_motor_1"/>
          <geom pos="0 0 -0.0036" type="mesh" rgba="0.7 0.7 0.7 1" mesh="metacarpal_1"/>
          <body name="MCP_motor_1" pos="0.0106 0.0435 -0.0116">
            <joint name="MCP_1" pos="0 0 0" axis="-1 0 0" range="-2 2"/>
            <geom pos="-0.0106 -0.0435 0.008" type="mesh" rgba="0.7 0.7 0.7 1" mesh="MCP_motor_1"/>
            <geom pos="-0.0106 -0.0435 0.008" type="mesh" rgba="0.7 0.7 0.7 1" mesh="proximal_1"/>
            <body name="PIP_DIP_motor_1" pos="0 0.059 0">
              <joint name="PIP_1" pos="0 0 0" axis="-1 0 0" range="-2 2"/>
              <geom pos="-0.0106 -0.1025 0.008" type="mesh" rgba="0.7 0.7 0.7 1" mesh="PIP_DIP_motor_1"/>
              <geom pos="-0.0106 -0.1025 0.008" type="mesh" rgba="0.7 0.7 0.7 1" mesh="middle_1"/>
              <body name="distal_1" pos="0.0029 0.0505 0">
                <joint name="DIP_1" pos="0 0 0" axis="1 0 0" range="-2 2"/>
                <geom pos="-0.0135 -0.153 0.008" type="mesh" rgba="0.7 0.7 0.7 1" mesh="distal_1"/>
              </body>
            </body>
          </body>
        </body>
      </body>
      <body name="finger_2" pos="-0.11 0 0.006" quat="0.707107 0 0 0.707107">
        <geom size="0.015 0.02 0.002" pos="0 -0.01 0.007" type="box" rgba="0.1 1 0.1 1"/>
        <geom type="mesh" rgba="0.7 0.7 0.7 1" mesh="base_link"/>
        <body name="MCP_spread_motor_2" pos="0 0 0.0036">
          <joint name="MCP_spread_2" pos="0 0 0" axis="0 0 -1" range="-2 2"/>
          <geom pos="0 0 -0.0036" type="mesh" rgba="0.7 0.7 0.7 1" mesh="MCP_spread_motor_1"/>
          <geom pos="0 0 -0.0036" type="mesh" rgba="0.7 0.7 0.7 1" mesh="metacarpal_1"/>
          <body name="MCP_motor_2" pos="0.0106 0.0435 -0.0116">
            <joint name="MCP_2" pos="0 0 0" axis="-1 0 0" range="-2 2"/>
            <geom pos="-0.0106 -0.0435 0.008" type="mesh" rgba="0.7 0.7 0.7 1" mesh="MCP_motor_1"/>
            <geom pos="-0.0106 -0.0435 0.008" type="mesh" rgba="0.7 0.7 0.7 1" mesh="proximal_1"/>
            <body name="PIP_DIP_motor__2" pos="0 0.059 0">
              <joint name="PIP_2" pos="0 0 0" axis="-1 0 0" range="-2 2"/>
              <geom pos="-0.0106 -0.1025 0.008" type="mesh" rgba="0.7 0.7 0.7 1" mesh="PIP_DIP_motor_1"/>
              <geom pos="-0.0106 -0.1025 0.008" type="mesh" rgba="0.7 0.7 0.7 1" mesh="middle_1"/>
              <body name="distal_2" pos="0.0029 0.0505 0">
                <joint name="DIP_2" pos="0 0 0" axis="1 0 0" range="-2 2"/>
                <geom pos="-0.0135 -0.153 0.008" type="mesh" rgba="0.7 0.7 0.7 1" mesh="distal_1"/>
              </body>
            </body>
          </body>
        </body>
      </body>
      <body name="finger_3" pos="-0.11 0.06 0.006" quat="0.707107 0 0 0.707107">
        <geom size="0.015 0.02 0.002" pos="0 -0.01 0.007" type="box" rgba="0.1 1 0.1 1"/>
        <geom type="mesh" rgba="0.7 0.7 0.7 1" mesh="base_link"/>
        <body name="MCP_spread_motor_3" pos="0 0 0.0036">
          <joint name="MCP_spread_3" pos="0 0 0" axis="0 0 -1" range="-2 2"/>
          <geom pos="0 0 -0.0036" type="mesh" rgba="0.7 0.7 0.7 1" mesh="MCP_spread_motor_1"/>
          <geom pos="0 0 -0.0036" type="mesh" rgba="0.7 0.7 0.7 1" mesh="metacarpal_1"/>
          <body name="MCP_motor_3" pos="0.0106 0.0435 -0.0116">
            <joint name="MCP_3" pos="0 0 0" axis="-1 0 0" range="-2 2"/>
            <geom pos="-0.0106 -0.0435 0.008" type="mesh" rgba="0.7 0.7 0.7 1" mesh="MCP_motor_1"/>
            <geom pos="-0.0106 -0.0435 0.008" type="mesh" rgba="0.7 0.7 0.7 1" mesh="proximal_1"/>
            <body name="PIP_DIP_motor_3" pos="0 0.059 0">
              <joint name="PIP_3" pos="0 0 0" axis="-1 0 0" range="-2 2"/>
              <geom pos="-0.0106 -0.1025 0.008" type="mesh" rgba="0.7 0.7 0.7 1" mesh="PIP_DIP_motor_1"/>
              <geom pos="-0.0106 -0.1025 0.008" type="mesh" rgba="0.7 0.7 0.7 1" mesh="middle_1"/>
              <body name="distal_3" pos="0.0029 0.0505 0">
                <joint name="DIP_3" pos="0 0 0" axis="1 0 0" range="-2 2"/>
                <geom pos="-0.0135 -0.153 0.008" type="mesh" rgba="0.7 0.7 0.7 1" mesh="distal_1"/>
              </body>
            </body>
          </body>
        </body>
      </body>
      <body name="finger_4" pos="-0.11 -0.06 0.006" quat="0.707107 0 0 0.707107">
        <geom size="0.015 0.02 0.002" pos="0 -0.01 0.007" type="box" rgba="0.1 1 0.1 1"/>
        <geom type="mesh" rgba="0.7 0.7 0.7 1" mesh="base_link"/>
        <body name="MCP_spread_motor_4" pos="0 0 0.0036">
          <joint name="MCP_spread_4" pos="0 0 0" axis="0 0 -1" range="-2 2"/>
          <geom pos="0 0 -0.0036" type="mesh" rgba="0.7 0.7 0.7 1" mesh="MCP_spread_motor_1"/>
          <geom pos="0 0 -0.0036" type="mesh" rgba="0.7 0.7 0.7 1" mesh="metacarpal_1"/>
          <body name="MCP_motor_4" pos="0.0106 0.0435 -0.0116">
            <joint name="MCP_4" pos="0 0 0" axis="-1 0 0" range="-2 2"/>
            <geom pos="-0.0106 -0.0435 0.008" type="mesh" rgba="0.7 0.7 0.7 1" mesh="MCP_motor_1"/>
            <geom pos="-0.0106 -0.0435 0.008" type="mesh" rgba="0.7 0.7 0.7 1" mesh="proximal_1"/>
            <body name="PIP_DIP_motor_4" pos="0 0.059 0">
              <joint name="PIP_4" pos="0 0 0" axis="-1 0 0" range="-2 2"/>
              <geom pos="-0.0106 -0.1025 0.008" type="mesh" rgba="0.7 0.7 0.7 1" mesh="PIP_DIP_motor_1"/>
              <geom pos="-0.0106 -0.1025 0.008" type="mesh" rgba="0.7 0.7 0.7 1" mesh="middle_1"/>
              <body name="distal_4" pos="0.0029 0.0505 0">
                <joint name="DIP_4" pos="0 0 0" axis="1 0 0" range="-2 2"/>
                <geom pos="-0.0135 -0.153 0.008" type="mesh" rgba="0.7 0.7 0.7 1" mesh="distal_1"/>
              </body>
            </body>
          </body>
        </body>
      </body>
      <body name="finger_5" pos="-0.05 -0.11 0.006" quat="0 0 0 1">
        <geom size="0.015 0.02 0.002" pos="0 -0.01 0.007" type="box" rgba="0.1 1 0.1 1"/>
        <geom type="mesh" rgba="0.7 0.7 0.7 1" mesh="base_link"/>
        <body name="MCP_spread_motor_5" pos="0 0 0.0036">
          <joint name="MCP_spread_5" pos="0 0 0" axis="0 0 -1" range="-2 2"/>
          <geom pos="0 0 -0.0036" type="mesh" rgba="0.7 0.7 0.7 1" mesh="MCP_spread_motor_1"/>
          <geom pos="0 0 -0.0036" type="mesh" rgba="0.7 0.7 0.7 1" mesh="metacarpal_1"/>
          <body name="MCP_motor_5" pos="0.0106 0.0435 -0.0116">
            <joint name="MCP_5" pos="0 0 0" axis="-1 0 0" range="-2 2"/>
            <geom pos="-0.0106 -0.0435 0.008" type="mesh" rgba="0.7 0.7 0.7 1" mesh="MCP_motor_1"/>
            <geom pos="-0.0106 -0.0435 0.008" type="mesh" rgba="0.7 0.7 0.7 1" mesh="proximal_1"/>
            <body name="PIP_DIP_motor_5" pos="0 0.059 0">
              <joint name="PIP_5" pos="0 0 0" axis="-1 0 0" range="-2 2"/>
              <geom pos="-0.0106 -0.1025 0.008" type="mesh" rgba="0.7 0.7 0.7 1" mesh="PIP_DIP_motor_1"/>
              <geom pos="-0.0106 -0.1025 0.008" type="mesh" rgba="0.7 0.7 0.7 1" mesh="middle_1"/>
              <body name="distal_5" pos="0.0029 0.0505 0">
                <joint name="DIP_5" pos="0 0 0" axis="1 0 0" range="-2 2"/>
                <geom pos="-0.0135 -0.153 0.008" type="mesh" rgba="0.7 0.7 0.7 1" mesh="distal_1"/>
              </body>
            </body>
          </body>
        </body>
      </body>
      <body name="finger_6" pos="0.05 -0.11 0.006" quat="0 0 0 1">
        <geom size="0.015 0.02 0.002" pos="0 -0.01 0.007" type="box" rgba="0.1 1 0.1 1"/>
        <geom type="mesh" rgba="0.7 0.7 0.7 1" mesh="base_link"/>
        <body name="MCP_spread_motor_6" pos="0 0 0.0036">
          <joint name="MCP_spread_6" pos="0 0 0" axis="0 0 -1" range="-2 2"/>
          <geom pos="0 0 -0.0036" type="mesh" rgba="0.7 0.7 0.7 1" mesh="MCP_spread_motor_1"/>
          <geom pos="0 0 -0.0036" type="mesh" rgba="0.7 0.7 0.7 1" mesh="metacarpal_1"/>
          <body name="MCP_motor_6" pos="0.0106 0.0435 -0.0116">
            <joint name="MCP_6" pos="0 0 0" axis="-1 0 0" range="-2 2"/>
            <geom pos="-0.0106 -0.0435 0.008" type="mesh" rgba="0.7 0.7 0.7 1" mesh="MCP_motor_1"/>
            <geom pos="-0.0106 -0.0435 0.008" type="mesh" rgba="0.7 0.7 0.7 1" mesh="proximal_1"/>
            <body name="PIP_DIP_motor_6" pos="0 0.059 0">
              <joint name="PIP_6" pos="0 0 0" axis="-1 0 0" range="-2 2"/>
              <geom pos="-0.0106 -0.1025 0.008" type="mesh" rgba="0.7 0.7 0.7 1" mesh="PIP_DIP_motor_1"/>
              <geom pos="-0.0106 -0.1025 0.008" type="mesh" rgba="0.7 0.7 0.7 1" mesh="middle_1"/>
              <body name="distal_6" pos="0.0029 0.0505 0">
                <joint name="DIP_6" pos="0 0 0" axis="1 0 0" range="-2 2"/>
                <geom pos="-0.0135 -0.153 0.008" type="mesh" rgba="0.7 0.7 0.7 1" mesh="distal_1"/>
              </body>
            </body>
          </body>
        </body>
      </body>
    </body>
  </worldbody>
  <actuator>
    <general name="joint_11" joint="MCP_spread_1" ctrlrange="-3 3"/>
    <general name="joint_12" joint="MCP_1" ctrlrange="-3 3"/>
    <general name="joint_13" joint="PIP_1" ctrlrange="-3 3"/>
    <general name="joint_14" joint="DIP_1" ctrlrange="-3 3"/>
    <general name="joint_21" joint="MCP_spread_2" ctrlrange="-3 3"/>
    <general name="joint_22" joint="MCP_2" ctrlrange="-3 3"/>
    <general name="joint_23" joint="PIP_2" ctrlrange="-3 3"/>
    <general name="joint_24" joint="DIP_2" ctrlrange="-3 3"/>
    <general name="joint_31" joint="MCP_spread_3" ctrlrange="-3 3"/>
    <general name="joint_32" joint="MCP_3" ctrlrange="-3 3"/>
    <general name="joint_33" joint="PIP_3" ctrlrange="-3 3"/>
    <general name="joint_34" joint="DIP_3" ctrlrange="-3 3"/>
    <general name="joint_41" joint="MCP_spread_4" ctrlrange="-3 3"/>
    <general name="joint_42" joint="MCP_4" ctrlrange="-3 3"/>
    <general name="joint_43" joint="PIP_4" ctrlrange="-3 3"/>
    <general name="joint_44" joint="DIP_4" ctrlrange="-3 3"/>
    <general name="joint_51" joint="MCP_spread_5" ctrlrange="-3 3"/>
    <general name="joint_52" joint="MCP_5" ctrlrange="-3 3"/>
    <general name="joint_53" joint="PIP_5" ctrlrange="-3 3"/>
    <general name="joint_54" joint="DIP_5" ctrlrange="-3 3"/>
    <general name="joint_61" joint="MCP_spread_6" ctrlrange="-3 3"/>
    <general name="joint_62" joint="MCP_6" ctrlrange="-3 3"/>
    <general name="joint_63" joint="PIP_6" ctrlrange="-3 3"/>
    <general name="joint_64" joint="DIP_6" ctrlrange="-3 3"/>
  </actuator>
</mujoco>
