<mujoco model="URDF_finger_ssss">
    <compiler angle="radian" meshdir="/home/xiao/research/lasa/mujoco_new/crawling_robot/single_finger/shortest/meshes/" />
    <size njmax="500" nconmax="100" />

    <option>
        <flag gravity="disable"/>
    </option>

    <asset>
        <mesh name="base_link" file="base_link.stl" scale="0.001 0.001 0.001" />
        <mesh name="MCP_spread_motor_1" file="MCP_spread_motor_1.stl" scale="0.001 0.001 0.001" />
        <mesh name="MCP_motor_1" file="MCP_motor_1.stl" scale="0.001 0.001 0.001" />
        <mesh name="proximal_1" file="proximal_1.stl" scale="0.001 0.001 0.001" />
        <mesh name="PIP_DIP_motor_1" file="PIP_DIP_motor_1.stl" scale="0.001 0.001 0.001" />
        <mesh name="middle_1" file="middle_1.stl" scale="0.001 0.001 0.001" />
        <mesh name="distal_1" file="distal_1.stl" scale="0.001 0.001 0.001" />
        <mesh name="metacarpal_1" file="metacarpal_1.stl" scale="0.001 0.001 0.001" />
    </asset>
    <worldbody>
        <geom type="mesh" rgba="0.7 0.7 0.7 1" mesh="base_link" />
        <body name="MCP_spread_motor_1" pos="0 0 0.0036">
            <inertial pos="0.000245265 -0.00496883 -0.0114693" quat="0.524663 0.474196 -0.523113 0.475625" mass="0.21816" diaginertia="5.65844e-05 4.36866e-05 3.19042e-05" />
            <joint name="MCP_spread" pos="0 0 0" axis="0 0 -1" />
            <geom pos="0 0 -0.0036" type="mesh" rgba="0.7 0.7 0.7 1" mesh="MCP_spread_motor_1" />
            <geom pos="0 0 -0.0036" type="mesh" rgba="0.7 0.7 0.7 1" mesh="metacarpal_1" />
            <body name="MCP_motor_1" pos="0.0106 0.0235 -0.0116">
                <inertial pos="-0.0103512 0.0125458 3.30732e-06" quat="0.535591 0.461692 -0.535523 0.461734" mass="0.151474" diaginertia="3.89252e-05 3.18099e-05 1.61153e-05" />
                <joint name="MCP" pos="0 0 0" axis="-1 0 0" />
                <geom pos="-0.0106 -0.0235 0.008" type="mesh" rgba="0.7 0.7 0.7 1" mesh="MCP_motor_1" />
                <geom pos="-0.0106 -0.0235 0.008" type="mesh" rgba="0.7 0.7 0.7 1" mesh="proximal_1" />
                <body name="PIP_DIP_motor_1" pos="0 0.039 0">
                    <inertial pos="-0.010709 0.0103943 3.56469e-06" quat="0.533676 0.463904 -0.533611 0.463942" mass="0.140537" diaginertia="2.81223e-05 2.20307e-05 1.40916e-05" />
                    <joint name="PIP" pos="0 0 0" axis="-1 0 0" />
                    <geom pos="-0.0106 -0.0625 0.008" type="mesh" rgba="0.7 0.7 0.7 1" mesh="PIP_DIP_motor_1" />
                    <geom pos="-0.0106 -0.0625 0.008" type="mesh" rgba="0.7 0.7 0.7 1" mesh="middle_1" />
                    <body name="distal_1" pos="0.0029 0.0305 0">
                        <inertial pos="-0.0135 0.0167496 0" quat="0.5 0.5 -0.5 0.5" mass="0.112487" diaginertia="1.8e-05 1.7e-05 8e-06" />
                        <joint name="DIP" pos="0 0 0" axis="1 0 0" />
                        <geom pos="-0.0135 -0.093 0.008" type="mesh" rgba="0.7 0.7 0.7 1" mesh="distal_1" />
                    </body>
                </body>
            </body>
        </body>
    </worldbody>

    <equality>
        <joint joint1="PIP" joint2="DIP" polycoef="0 -1 0 0 0"/>
    </equality>

    <actuator>
        <position name="joint_01" ctrllimited="true" ctrlrange="-1.0 1.0" joint="MCP_spread" />
        <position name="joint_02" ctrllimited="true" ctrlrange="-1.0 1.0" joint="MCP" />
        <position name="joint_03" ctrllimited="true" ctrlrange="-1.0 1.0" joint="PIP" />
  </actuator>

</mujoco>
