<?xml version="1.0" ?>
<robot name="converted_robot">
   <link name="world">
      <inertial>
         <origin xyz="0.0 0.0 0.0" rpy="0.0 0.0 0.0"/>
         <mass value="0.0"/>
         <inertia ixx="0.0" iyy="0.0" izz="0.0" ixy="0" ixz="0" iyz="0"/>
      </inertial>
   </link>
   <link name="hand">
      <inertial>
         <origin xyz="0.0 0.0 0.0" rpy="0.0 0.0 0.0"/>
         <mass value="0.5120000000000001"/>
         <inertia ixx="0.0011093333333333337" iyy="0.0011093333333333337" izz="0.002184533333333334" ixy="0" ixz="0" iyz="0"/>
      </inertial>
      <visual name="hand">
         <origin xyz="0. 0. 0." rpy="0. 0. 0."/>
         <geometry>
            <box size="0.16 0.16 0.02"/>
            <material name="white"/>
         </geometry>
      </visual>
   </link>
   <link name="world2world_fixed">
      <inertial>
         <origin xyz="0.0 0.0 0.0" rpy="0.0 0.0 0.0"/>
         <mass value="0.001"/>
         <inertia ixx="1e-09" iyy="1e-09" izz="1e-09" ixy="0" ixz="0" iyz="0"/>
      </inertial>
   </link>
   <joint type="fixed" name="world2world_fixed">
      <parent link="world"/>
      <child link="world2world_fixed"/>
      <origin xyz="0.0 0.0 0.01" rpy="0.0 0.0 0.0"/>
   </joint>
   <joint type="fixed" name="world2world_fixed_offset">
      <parent link="world2world_fixed"/>
      <child link="hand"/>
      <origin xyz="-0.0 -0.0 -0.0" rpy="0.0 0.0 0.0"/>
   </joint>
   <link name="finger_1">
      <inertial>
         <origin xyz="7.486488586106731e-09 -0.008795409811483749 0.00671379288753095" rpy="-5.62659578494751e-15 -1.551063345751673 1.5707963267949023"/>
         <mass value="0.005457218797018834"/>
         <inertia ixx="1.0756152518385642e-06" iyy="7.171729164374252e-07" izz="3.790810947574593e-07" ixy="0" ixz="0" iyz="0"/>
      </inertial>
      <visual name="base_link">
         <origin xyz="6.216408663460327e-08 2.3192417713995757e-06 0.004623478145951719" rpy="3.141592653589793 -1.5707963267948966 0.0"/>
         <geometry>
            <mesh filename="package://converted_base_link.stl"/>
         </geometry>
         <material name="white"/>
      </visual>
   </link>
   <link name="hand2finger_1_fixed">
      <inertial>
         <origin xyz="0.0 0.0 0.0" rpy="0.0 0.0 0.0"/>
         <mass value="0.001"/>
         <inertia ixx="1e-09" iyy="1e-09" izz="1e-09" ixy="0" ixz="0" iyz="0"/>
      </inertial>
   </link>
   <joint type="fixed" name="hand2finger_1_fixed">
      <parent link="hand"/>
      <child link="hand2finger_1_fixed"/>
      <origin xyz="0.0 0.11 0.006" rpy="0.0 0.0 0.0"/>
   </joint>
   <joint type="fixed" name="hand2finger_1_fixed_offset">
      <parent link="hand2finger_1_fixed"/>
      <child link="finger_1"/>
      <origin xyz="-0.0 -0.0 -0.0" rpy="0.0 0.0 0.0"/>
   </joint>
   <link name="MCP_spread_motor_1">
      <inertial>
         <origin xyz="0.0003982548390317494 0.006056317763366704 -0.011559460451449984" rpy="0.19370178971530685 -1.5691490208487457 1.3077529046197847"/>
         <mass value="0.06051675954815346"/>
         <inertia ixx="2.814235433465105e-05" iyy="2.3892426850630282e-05" izz="7.857098025414057e-06" ixy="0" ixz="0" iyz="0"/>
      </inertial>
      <visual name="MCP_spread_motor_1">
         <origin xyz="-4.635344990172431e-05 -0.007515921440695716 -0.011428398130128803" rpy="1.5716895445470493 -0.03571975389681192 -0.004558496347485136"/>
         <geometry>
            <mesh filename="package://converted_MCP_spread_motor_1.stl"/>
         </geometry>
         <material name="white"/>
      </visual>
      <visual name="metacarpal_1">
         <origin xyz="0.0005359663967735601 0.01026013998026553 -0.01160005527813145" rpy="0.9396397687264357 -1.5707910814168278 0.5458940371703993"/>
         <geometry>
            <mesh filename="package://converted_metacarpal_1.stl"/>
         </geometry>
         <material name="white"/>
      </visual>
   </link>
   <link name="MCP_spread_1">
      <inertial>
         <origin xyz="0.0 0.0 0.0" rpy="0.0 0.0 0.0"/>
         <mass value="0.001"/>
         <inertia ixx="1e-09" iyy="1e-09" izz="1e-09" ixy="0" ixz="0" iyz="0"/>
      </inertial>
   </link>
   <joint type="revolute" name="MCP_spread_1">
      <parent link="finger_1"/>
      <child link="MCP_spread_1"/>
      <origin xyz="0.0 0.0 0.0036" rpy="0.0 0.0 0.0"/>
      <axis xyz="0.0 0.0 -1.0"/>
      <limit lower="-2.0" upper="2.0" effort="100" velocity="100"/>
   </joint>
   <joint type="fixed" name="MCP_spread_1_offset">
      <parent link="MCP_spread_1"/>
      <child link="MCP_spread_motor_1"/>
      <origin xyz="-0.0 -0.0 -0.0" rpy="0.0 0.0 0.0"/>
   </joint>
   <link name="MCP_motor_1">
      <inertial>
         <origin xyz="-0.010500762855210177 0.0279346378824954 -1.6453546218841143e-05" rpy="2.2142146406693315 -1.569753519206229 -0.7069429676930239"/>
         <mass value="0.04035147436542081"/>
         <inertia ixx="1.9492629690810927e-05" iyy="1.6523224440094084e-05" izz="4.743306102438892e-06" ixy="0" ixz="0" iyz="0"/>
      </inertial>
      <visual name="MCP_motor_1">
         <origin xyz="-0.011428398088521013 0.007515922825152364 -4.6353117932732e-05" rpy="1.4447302968900833 -1.5347869918721169 0.12687784385510545"/>
         <geometry>
            <mesh filename="package://converted_MCP_motor_1.stl"/>
         </geometry>
         <material name="white"/>
      </visual>
      <visual name="proximal_1">
         <origin xyz="-0.009990938238875247 0.03915668206144257 -2.086111781582356e-08" rpy="1.3774808759047128 -1.5707963267948966 0.0"/>
         <geometry>
            <mesh filename="package://converted_proximal_1.stl"/>
         </geometry>
         <material name="white"/>
      </visual>
   </link>
   <link name="MCP_1">
      <inertial>
         <origin xyz="0.0 0.0 0.0" rpy="0.0 0.0 0.0"/>
         <mass value="0.001"/>
         <inertia ixx="1e-09" iyy="1e-09" izz="1e-09" ixy="0" ixz="0" iyz="0"/>
      </inertial>
   </link>
   <joint type="revolute" name="MCP_1">
      <parent link="MCP_spread_motor_1"/>
      <child link="MCP_1"/>
      <origin xyz="0.0106 0.0435 -0.0116" rpy="0.0 0.0 0.0"/>
      <axis xyz="-1.0 0.0 0.0"/>
      <limit lower="-2.0" upper="2.0" effort="100" velocity="100"/>
   </joint>
   <joint type="fixed" name="MCP_1_offset">
      <parent link="MCP_1"/>
      <child link="MCP_motor_1"/>
      <origin xyz="-0.0 -0.0 -0.0" rpy="0.0 0.0 0.0"/>
   </joint>
   <link name="PIP_DIP_motor_1">
      <inertial>
         <origin xyz="-0.010914824701867876 0.02295944687359636 -1.8105084342263588e-05" rpy="2.242184262995694 -1.5697116962013469 -0.6928341602075203"/>
         <mass value="0.036640934606382555"/>
         <inertia ixx="1.3325542894551051e-05" iyy="1.0628111048812819e-05" izz="4.3975503665319475e-06" ixy="0" ixz="0" iyz="0"/>
      </inertial>
      <visual name="PIP_DIP_motor_1">
         <origin xyz="-0.011428398389228734 0.007515925594064665 -4.635318888735612e-05" rpy="1.444729319926511 -1.5347868813838343 0.12687878859745186"/>
         <geometry>
            <mesh filename="package://converted_PIP_DIP_motor_1.stl"/>
         </geometry>
         <material name="white"/>
      </visual>
      <visual name="middle_1">
         <origin xyz="-0.01058566312317408 0.032857566598312835 -2.0296691237431386e-10" rpy="2.9223690462600653 -1.5707963267948966 0.0"/>
         <geometry>
            <mesh filename="package://converted_middle_1.stl"/>
         </geometry>
         <material name="white"/>
      </visual>
   </link>
   <link name="PIP_1">
      <inertial>
         <origin xyz="0.0 0.0 0.0" rpy="0.0 0.0 0.0"/>
         <mass value="0.001"/>
         <inertia ixx="1e-09" iyy="1e-09" izz="1e-09" ixy="0" ixz="0" iyz="0"/>
      </inertial>
   </link>
   <joint type="revolute" name="PIP_1">
      <parent link="MCP_motor_1"/>
      <child link="PIP_1"/>
      <origin xyz="0.0 0.059 0.0" rpy="0.0 0.0 0.0"/>
      <axis xyz="-1.0 0.0 0.0"/>
      <limit lower="-2.0" upper="2.0" effort="100" velocity="100"/>
   </joint>
   <joint type="fixed" name="PIP_1_offset">
      <parent link="PIP_1"/>
      <child link="PIP_DIP_motor_1"/>
      <origin xyz="-0.0 -0.0 -0.0" rpy="0.0 0.0 0.0"/>
   </joint>
   <link name="distal_1">
      <inertial>
         <origin xyz="-0.013499999980733406 0.026097314775325453 5.960085598319398e-08" rpy="3.141592653589793 -1.570791449970143 -1.5707963267948966"/>
         <mass value="0.02347525072396419"/>
         <inertia ixx="6.947379008048446e-06" iyy="6.706879032267138e-06" izz="1.6774041387410145e-06" ixy="0" ixz="0" iyz="0"/>
      </inertial>
      <visual name="distal_1">
         <origin xyz="-0.013499999980733406 0.026097314775325453 5.960085598319398e-08" rpy="3.141592653589793 -1.570791449970143 -1.5707963267948966"/>
         <geometry>
            <mesh filename="package://converted_distal_1.stl"/>
         </geometry>
         <material name="white"/>
      </visual>
   </link>
   <link name="DIP_1">
      <inertial>
         <origin xyz="0.0 0.0 0.0" rpy="0.0 0.0 0.0"/>
         <mass value="0.001"/>
         <inertia ixx="1e-09" iyy="1e-09" izz="1e-09" ixy="0" ixz="0" iyz="0"/>
      </inertial>
   </link>
   <joint type="revolute" name="DIP_1">
      <parent link="PIP_DIP_motor_1"/>
      <child link="DIP_1"/>
      <origin xyz="0.0029 0.0505 0.0" rpy="0.0 0.0 0.0"/>
      <axis xyz="1.0 0.0 0.0"/>
      <limit lower="-2.0" upper="2.0" effort="100" velocity="100"/>
   </joint>
   <joint type="fixed" name="DIP_1_offset">
      <parent link="DIP_1"/>
      <child link="distal_1"/>
      <origin xyz="-0.0 -0.0 -0.0" rpy="0.0 0.0 0.0"/>
   </joint>
   <link name="finger_2">
      <inertial>
         <origin xyz="7.486488586106731e-09 -0.008795409811483749 0.00671379288753095" rpy="-5.62659578494751e-15 -1.551063345751673 1.5707963267949023"/>
         <mass value="0.005457218797018834"/>
         <inertia ixx="1.0756152518385642e-06" iyy="7.171729164374252e-07" izz="3.790810947574593e-07" ixy="0" ixz="0" iyz="0"/>
      </inertial>
      <visual name="base_link">
         <origin xyz="6.216408663460327e-08 2.3192417713995757e-06 0.004623478145951719" rpy="3.141592653589793 -1.5707963267948966 0.0"/>
         <geometry>
            <mesh filename="package://converted_base_link.stl"/>
         </geometry>
         <material name="white"/>
      </visual>
   </link>
   <link name="hand2finger_2_fixed">
      <inertial>
         <origin xyz="0.0 0.0 0.0" rpy="0.0 0.0 0.0"/>
         <mass value="0.001"/>
         <inertia ixx="1e-09" iyy="1e-09" izz="1e-09" ixy="0" ixz="0" iyz="0"/>
      </inertial>
   </link>
   <joint type="fixed" name="hand2finger_2_fixed">
      <parent link="hand"/>
      <child link="hand2finger_2_fixed"/>
      <origin xyz="-0.11 0.0 0.006" rpy="0.0 0.0 1.5707963267948963"/>
   </joint>
   <joint type="fixed" name="hand2finger_2_fixed_offset">
      <parent link="hand2finger_2_fixed"/>
      <child link="finger_2"/>
      <origin xyz="-0.0 -0.0 -0.0" rpy="0.0 0.0 0.0"/>
   </joint>
   <link name="MCP_spread_motor_2">
      <inertial>
         <origin xyz="0.0003982548390317494 0.006056317763366704 -0.011559460451449984" rpy="0.19370178971530685 -1.5691490208487457 1.3077529046197847"/>
         <mass value="0.06051675954815346"/>
         <inertia ixx="2.814235433465105e-05" iyy="2.3892426850630282e-05" izz="7.857098025414057e-06" ixy="0" ixz="0" iyz="0"/>
      </inertial>
      <visual name="MCP_spread_motor_1">
         <origin xyz="-4.635344990172431e-05 -0.007515921440695716 -0.011428398130128803" rpy="1.5716895445470493 -0.03571975389681192 -0.004558496347485136"/>
         <geometry>
            <mesh filename="package://converted_MCP_spread_motor_1.stl"/>
         </geometry>
         <material name="white"/>
      </visual>
      <visual name="metacarpal_1">
         <origin xyz="0.0005359663967735601 0.01026013998026553 -0.01160005527813145" rpy="0.9396397687264357 -1.5707910814168278 0.5458940371703993"/>
         <geometry>
            <mesh filename="package://converted_metacarpal_1.stl"/>
         </geometry>
         <material name="white"/>
      </visual>
   </link>
   <link name="MCP_spread_2">
      <inertial>
         <origin xyz="0.0 0.0 0.0" rpy="0.0 0.0 0.0"/>
         <mass value="0.001"/>
         <inertia ixx="1e-09" iyy="1e-09" izz="1e-09" ixy="0" ixz="0" iyz="0"/>
      </inertial>
   </link>
   <joint type="revolute" name="MCP_spread_2">
      <parent link="finger_2"/>
      <child link="MCP_spread_2"/>
      <origin xyz="0.0 0.0 0.0036" rpy="0.0 0.0 0.0"/>
      <axis xyz="0.0 0.0 -1.0"/>
      <limit lower="-2.0" upper="2.0" effort="100" velocity="100"/>
   </joint>
   <joint type="fixed" name="MCP_spread_2_offset">
      <parent link="MCP_spread_2"/>
      <child link="MCP_spread_motor_2"/>
      <origin xyz="-0.0 -0.0 -0.0" rpy="0.0 0.0 0.0"/>
   </joint>
   <link name="MCP_motor_2">
      <inertial>
         <origin xyz="-0.010500762855210177 0.0279346378824954 -1.6453546218841143e-05" rpy="2.2142146406693315 -1.569753519206229 -0.7069429676930239"/>
         <mass value="0.04035147436542081"/>
         <inertia ixx="1.9492629690810927e-05" iyy="1.6523224440094084e-05" izz="4.743306102438892e-06" ixy="0" ixz="0" iyz="0"/>
      </inertial>
      <visual name="MCP_motor_1">
         <origin xyz="-0.011428398088521013 0.007515922825152364 -4.6353117932732e-05" rpy="1.4447302968900833 -1.5347869918721169 0.12687784385510545"/>
         <geometry>
            <mesh filename="package://converted_MCP_motor_1.stl"/>
         </geometry>
         <material name="white"/>
      </visual>
      <visual name="proximal_1">
         <origin xyz="-0.009990938238875247 0.03915668206144257 -2.086111781582356e-08" rpy="1.3774808759047128 -1.5707963267948966 0.0"/>
         <geometry>
            <mesh filename="package://converted_proximal_1.stl"/>
         </geometry>
         <material name="white"/>
      </visual>
   </link>
   <link name="MCP_2">
      <inertial>
         <origin xyz="0.0 0.0 0.0" rpy="0.0 0.0 0.0"/>
         <mass value="0.001"/>
         <inertia ixx="1e-09" iyy="1e-09" izz="1e-09" ixy="0" ixz="0" iyz="0"/>
      </inertial>
   </link>
   <joint type="revolute" name="MCP_2">
      <parent link="MCP_spread_motor_2"/>
      <child link="MCP_2"/>
      <origin xyz="0.0106 0.0435 -0.0116" rpy="0.0 0.0 0.0"/>
      <axis xyz="-1.0 0.0 0.0"/>
      <limit lower="-2.0" upper="2.0" effort="100" velocity="100"/>
   </joint>
   <joint type="fixed" name="MCP_2_offset">
      <parent link="MCP_2"/>
      <child link="MCP_motor_2"/>
      <origin xyz="-0.0 -0.0 -0.0" rpy="0.0 0.0 0.0"/>
   </joint>
   <link name="PIP_DIP_motor__2">
      <inertial>
         <origin xyz="-0.010914824701867876 0.02295944687359636 -1.8105084342263588e-05" rpy="2.242184262995694 -1.5697116962013469 -0.6928341602075203"/>
         <mass value="0.036640934606382555"/>
         <inertia ixx="1.3325542894551051e-05" iyy="1.0628111048812819e-05" izz="4.3975503665319475e-06" ixy="0" ixz="0" iyz="0"/>
      </inertial>
      <visual name="PIP_DIP_motor_1">
         <origin xyz="-0.011428398389228734 0.007515925594064665 -4.635318888735612e-05" rpy="1.444729319926511 -1.5347868813838343 0.12687878859745186"/>
         <geometry>
            <mesh filename="package://converted_PIP_DIP_motor_1.stl"/>
         </geometry>
         <material name="white"/>
      </visual>
      <visual name="middle_1">
         <origin xyz="-0.01058566312317408 0.032857566598312835 -2.0296691237431386e-10" rpy="2.9223690462600653 -1.5707963267948966 0.0"/>
         <geometry>
            <mesh filename="package://converted_middle_1.stl"/>
         </geometry>
         <material name="white"/>
      </visual>
   </link>
   <link name="PIP_2">
      <inertial>
         <origin xyz="0.0 0.0 0.0" rpy="0.0 0.0 0.0"/>
         <mass value="0.001"/>
         <inertia ixx="1e-09" iyy="1e-09" izz="1e-09" ixy="0" ixz="0" iyz="0"/>
      </inertial>
   </link>
   <joint type="revolute" name="PIP_2">
      <parent link="MCP_motor_2"/>
      <child link="PIP_2"/>
      <origin xyz="0.0 0.059 0.0" rpy="0.0 0.0 0.0"/>
      <axis xyz="-1.0 0.0 0.0"/>
      <limit lower="-2.0" upper="2.0" effort="100" velocity="100"/>
   </joint>
   <joint type="fixed" name="PIP_2_offset">
      <parent link="PIP_2"/>
      <child link="PIP_DIP_motor__2"/>
      <origin xyz="-0.0 -0.0 -0.0" rpy="0.0 0.0 0.0"/>
   </joint>
   <link name="distal_2">
      <inertial>
         <origin xyz="-0.013499999980733406 0.026097314775325453 5.960085598319398e-08" rpy="3.141592653589793 -1.570791449970143 -1.5707963267948966"/>
         <mass value="0.02347525072396419"/>
         <inertia ixx="6.947379008048446e-06" iyy="6.706879032267138e-06" izz="1.6774041387410145e-06" ixy="0" ixz="0" iyz="0"/>
      </inertial>
      <visual name="distal_1">
         <origin xyz="-0.013499999980733406 0.026097314775325453 5.960085598319398e-08" rpy="3.141592653589793 -1.570791449970143 -1.5707963267948966"/>
         <geometry>
            <mesh filename="package://converted_distal_1.stl"/>
         </geometry>
         <material name="white"/>
      </visual>
   </link>
   <link name="DIP_2">
      <inertial>
         <origin xyz="0.0 0.0 0.0" rpy="0.0 0.0 0.0"/>
         <mass value="0.001"/>
         <inertia ixx="1e-09" iyy="1e-09" izz="1e-09" ixy="0" ixz="0" iyz="0"/>
      </inertial>
   </link>
   <joint type="revolute" name="DIP_2">
      <parent link="PIP_DIP_motor__2"/>
      <child link="DIP_2"/>
      <origin xyz="0.0029 0.0505 0.0" rpy="0.0 0.0 0.0"/>
      <axis xyz="1.0 0.0 0.0"/>
      <limit lower="-2.0" upper="2.0" effort="100" velocity="100"/>
   </joint>
   <joint type="fixed" name="DIP_2_offset">
      <parent link="DIP_2"/>
      <child link="distal_2"/>
      <origin xyz="-0.0 -0.0 -0.0" rpy="0.0 0.0 0.0"/>
   </joint>
   <link name="finger_3">
      <inertial>
         <origin xyz="7.486488586106731e-09 -0.008795409811483749 0.00671379288753095" rpy="-5.62659578494751e-15 -1.551063345751673 1.5707963267949023"/>
         <mass value="0.005457218797018834"/>
         <inertia ixx="1.0756152518385642e-06" iyy="7.171729164374252e-07" izz="3.790810947574593e-07" ixy="0" ixz="0" iyz="0"/>
      </inertial>
      <visual name="base_link">
         <origin xyz="6.216408663460327e-08 2.3192417713995757e-06 0.004623478145951719" rpy="3.141592653589793 -1.5707963267948966 0.0"/>
         <geometry>
            <mesh filename="package://converted_base_link.stl"/>
         </geometry>
         <material name="white"/>
      </visual>
   </link>
   <link name="hand2finger_3_fixed">
      <inertial>
         <origin xyz="0.0 0.0 0.0" rpy="0.0 0.0 0.0"/>
         <mass value="0.001"/>
         <inertia ixx="1e-09" iyy="1e-09" izz="1e-09" ixy="0" ixz="0" iyz="0"/>
      </inertial>
   </link>
   <joint type="fixed" name="hand2finger_3_fixed">
      <parent link="hand"/>
      <child link="hand2finger_3_fixed"/>
      <origin xyz="-0.11 0.06 0.006" rpy="0.0 0.0 1.5707963267948963"/>
   </joint>
   <joint type="fixed" name="hand2finger_3_fixed_offset">
      <parent link="hand2finger_3_fixed"/>
      <child link="finger_3"/>
      <origin xyz="-0.0 -0.0 -0.0" rpy="0.0 0.0 0.0"/>
   </joint>
   <link name="MCP_spread_motor_3">
      <inertial>
         <origin xyz="0.0003982548390317494 0.006056317763366704 -0.011559460451449984" rpy="0.19370178971530685 -1.5691490208487457 1.3077529046197847"/>
         <mass value="0.06051675954815346"/>
         <inertia ixx="2.814235433465105e-05" iyy="2.3892426850630282e-05" izz="7.857098025414057e-06" ixy="0" ixz="0" iyz="0"/>
      </inertial>
      <visual name="MCP_spread_motor_1">
         <origin xyz="-4.635344990172431e-05 -0.007515921440695716 -0.011428398130128803" rpy="1.5716895445470493 -0.03571975389681192 -0.004558496347485136"/>
         <geometry>
            <mesh filename="package://converted_MCP_spread_motor_1.stl"/>
         </geometry>
         <material name="white"/>
      </visual>
      <visual name="metacarpal_1">
         <origin xyz="0.0005359663967735601 0.01026013998026553 -0.01160005527813145" rpy="0.9396397687264357 -1.5707910814168278 0.5458940371703993"/>
         <geometry>
            <mesh filename="package://converted_metacarpal_1.stl"/>
         </geometry>
         <material name="white"/>
      </visual>
   </link>
   <link name="MCP_spread_3">
      <inertial>
         <origin xyz="0.0 0.0 0.0" rpy="0.0 0.0 0.0"/>
         <mass value="0.001"/>
         <inertia ixx="1e-09" iyy="1e-09" izz="1e-09" ixy="0" ixz="0" iyz="0"/>
      </inertial>
   </link>
   <joint type="revolute" name="MCP_spread_3">
      <parent link="finger_3"/>
      <child link="MCP_spread_3"/>
      <origin xyz="0.0 0.0 0.0036" rpy="0.0 0.0 0.0"/>
      <axis xyz="0.0 0.0 -1.0"/>
      <limit lower="-2.0" upper="2.0" effort="100" velocity="100"/>
   </joint>
   <joint type="fixed" name="MCP_spread_3_offset">
      <parent link="MCP_spread_3"/>
      <child link="MCP_spread_motor_3"/>
      <origin xyz="-0.0 -0.0 -0.0" rpy="0.0 0.0 0.0"/>
   </joint>
   <link name="MCP_motor_3">
      <inertial>
         <origin xyz="-0.010500762855210177 0.0279346378824954 -1.6453546218841143e-05" rpy="2.2142146406693315 -1.569753519206229 -0.7069429676930239"/>
         <mass value="0.04035147436542081"/>
         <inertia ixx="1.9492629690810927e-05" iyy="1.6523224440094084e-05" izz="4.743306102438892e-06" ixy="0" ixz="0" iyz="0"/>
      </inertial>
      <visual name="MCP_motor_1">
         <origin xyz="-0.011428398088521013 0.007515922825152364 -4.6353117932732e-05" rpy="1.4447302968900833 -1.5347869918721169 0.12687784385510545"/>
         <geometry>
            <mesh filename="package://converted_MCP_motor_1.stl"/>
         </geometry>
         <material name="white"/>
      </visual>
      <visual name="proximal_1">
         <origin xyz="-0.009990938238875247 0.03915668206144257 -2.086111781582356e-08" rpy="1.3774808759047128 -1.5707963267948966 0.0"/>
         <geometry>
            <mesh filename="package://converted_proximal_1.stl"/>
         </geometry>
         <material name="white"/>
      </visual>
   </link>
   <link name="MCP_3">
      <inertial>
         <origin xyz="0.0 0.0 0.0" rpy="0.0 0.0 0.0"/>
         <mass value="0.001"/>
         <inertia ixx="1e-09" iyy="1e-09" izz="1e-09" ixy="0" ixz="0" iyz="0"/>
      </inertial>
   </link>
   <joint type="revolute" name="MCP_3">
      <parent link="MCP_spread_motor_3"/>
      <child link="MCP_3"/>
      <origin xyz="0.0106 0.0435 -0.0116" rpy="0.0 0.0 0.0"/>
      <axis xyz="-1.0 0.0 0.0"/>
      <limit lower="-2.0" upper="2.0" effort="100" velocity="100"/>
   </joint>
   <joint type="fixed" name="MCP_3_offset">
      <parent link="MCP_3"/>
      <child link="MCP_motor_3"/>
      <origin xyz="-0.0 -0.0 -0.0" rpy="0.0 0.0 0.0"/>
   </joint>
   <link name="PIP_DIP_motor_3">
      <inertial>
         <origin xyz="-0.010914824701867876 0.02295944687359636 -1.8105084342263588e-05" rpy="2.242184262995694 -1.5697116962013469 -0.6928341602075203"/>
         <mass value="0.036640934606382555"/>
         <inertia ixx="1.3325542894551051e-05" iyy="1.0628111048812819e-05" izz="4.3975503665319475e-06" ixy="0" ixz="0" iyz="0"/>
      </inertial>
      <visual name="PIP_DIP_motor_1">
         <origin xyz="-0.011428398389228734 0.007515925594064665 -4.635318888735612e-05" rpy="1.444729319926511 -1.5347868813838343 0.12687878859745186"/>
         <geometry>
            <mesh filename="package://converted_PIP_DIP_motor_1.stl"/>
         </geometry>
         <material name="white"/>
      </visual>
      <visual name="middle_1">
         <origin xyz="-0.01058566312317408 0.032857566598312835 -2.0296691237431386e-10" rpy="2.9223690462600653 -1.5707963267948966 0.0"/>
         <geometry>
            <mesh filename="package://converted_middle_1.stl"/>
         </geometry>
         <material name="white"/>
      </visual>
   </link>
   <link name="PIP_3">
      <inertial>
         <origin xyz="0.0 0.0 0.0" rpy="0.0 0.0 0.0"/>
         <mass value="0.001"/>
         <inertia ixx="1e-09" iyy="1e-09" izz="1e-09" ixy="0" ixz="0" iyz="0"/>
      </inertial>
   </link>
   <joint type="revolute" name="PIP_3">
      <parent link="MCP_motor_3"/>
      <child link="PIP_3"/>
      <origin xyz="0.0 0.059 0.0" rpy="0.0 0.0 0.0"/>
      <axis xyz="-1.0 0.0 0.0"/>
      <limit lower="-2.0" upper="2.0" effort="100" velocity="100"/>
   </joint>
   <joint type="fixed" name="PIP_3_offset">
      <parent link="PIP_3"/>
      <child link="PIP_DIP_motor_3"/>
      <origin xyz="-0.0 -0.0 -0.0" rpy="0.0 0.0 0.0"/>
   </joint>
   <link name="distal_3">
      <inertial>
         <origin xyz="-0.013499999980733406 0.026097314775325453 5.960085598319398e-08" rpy="3.141592653589793 -1.570791449970143 -1.5707963267948966"/>
         <mass value="0.02347525072396419"/>
         <inertia ixx="6.947379008048446e-06" iyy="6.706879032267138e-06" izz="1.6774041387410145e-06" ixy="0" ixz="0" iyz="0"/>
      </inertial>
      <visual name="distal_1">
         <origin xyz="-0.013499999980733406 0.026097314775325453 5.960085598319398e-08" rpy="3.141592653589793 -1.570791449970143 -1.5707963267948966"/>
         <geometry>
            <mesh filename="package://converted_distal_1.stl"/>
         </geometry>
         <material name="white"/>
      </visual>
   </link>
   <link name="DIP_3">
      <inertial>
         <origin xyz="0.0 0.0 0.0" rpy="0.0 0.0 0.0"/>
         <mass value="0.001"/>
         <inertia ixx="1e-09" iyy="1e-09" izz="1e-09" ixy="0" ixz="0" iyz="0"/>
      </inertial>
   </link>
   <joint type="revolute" name="DIP_3">
      <parent link="PIP_DIP_motor_3"/>
      <child link="DIP_3"/>
      <origin xyz="0.0029 0.0505 0.0" rpy="0.0 0.0 0.0"/>
      <axis xyz="1.0 0.0 0.0"/>
      <limit lower="-2.0" upper="2.0" effort="100" velocity="100"/>
   </joint>
   <joint type="fixed" name="DIP_3_offset">
      <parent link="DIP_3"/>
      <child link="distal_3"/>
      <origin xyz="-0.0 -0.0 -0.0" rpy="0.0 0.0 0.0"/>
   </joint>
   <link name="finger_4">
      <inertial>
         <origin xyz="7.486488586106731e-09 -0.008795409811483749 0.00671379288753095" rpy="-5.62659578494751e-15 -1.551063345751673 1.5707963267949023"/>
         <mass value="0.005457218797018834"/>
         <inertia ixx="1.0756152518385642e-06" iyy="7.171729164374252e-07" izz="3.790810947574593e-07" ixy="0" ixz="0" iyz="0"/>
      </inertial>
      <visual name="base_link">
         <origin xyz="6.216408663460327e-08 2.3192417713995757e-06 0.004623478145951719" rpy="3.141592653589793 -1.5707963267948966 0.0"/>
         <geometry>
            <mesh filename="package://converted_base_link.stl"/>
         </geometry>
         <material name="white"/>
      </visual>
   </link>
   <link name="hand2finger_4_fixed">
      <inertial>
         <origin xyz="0.0 0.0 0.0" rpy="0.0 0.0 0.0"/>
         <mass value="0.001"/>
         <inertia ixx="1e-09" iyy="1e-09" izz="1e-09" ixy="0" ixz="0" iyz="0"/>
      </inertial>
   </link>
   <joint type="fixed" name="hand2finger_4_fixed">
      <parent link="hand"/>
      <child link="hand2finger_4_fixed"/>
      <origin xyz="-0.11 -0.06 0.006" rpy="0.0 0.0 1.5707963267948963"/>
   </joint>
   <joint type="fixed" name="hand2finger_4_fixed_offset">
      <parent link="hand2finger_4_fixed"/>
      <child link="finger_4"/>
      <origin xyz="-0.0 -0.0 -0.0" rpy="0.0 0.0 0.0"/>
   </joint>
   <link name="MCP_spread_motor_4">
      <inertial>
         <origin xyz="0.0003982548390317494 0.006056317763366704 -0.011559460451449984" rpy="0.19370178971530685 -1.5691490208487457 1.3077529046197847"/>
         <mass value="0.06051675954815346"/>
         <inertia ixx="2.814235433465105e-05" iyy="2.3892426850630282e-05" izz="7.857098025414057e-06" ixy="0" ixz="0" iyz="0"/>
      </inertial>
      <visual name="MCP_spread_motor_1">
         <origin xyz="-4.635344990172431e-05 -0.007515921440695716 -0.011428398130128803" rpy="1.5716895445470493 -0.03571975389681192 -0.004558496347485136"/>
         <geometry>
            <mesh filename="package://converted_MCP_spread_motor_1.stl"/>
         </geometry>
         <material name="white"/>
      </visual>
      <visual name="metacarpal_1">
         <origin xyz="0.0005359663967735601 0.01026013998026553 -0.01160005527813145" rpy="0.9396397687264357 -1.5707910814168278 0.5458940371703993"/>
         <geometry>
            <mesh filename="package://converted_metacarpal_1.stl"/>
         </geometry>
         <material name="white"/>
      </visual>
   </link>
   <link name="MCP_spread_4">
      <inertial>
         <origin xyz="0.0 0.0 0.0" rpy="0.0 0.0 0.0"/>
         <mass value="0.001"/>
         <inertia ixx="1e-09" iyy="1e-09" izz="1e-09" ixy="0" ixz="0" iyz="0"/>
      </inertial>
   </link>
   <joint type="revolute" name="MCP_spread_4">
      <parent link="finger_4"/>
      <child link="MCP_spread_4"/>
      <origin xyz="0.0 0.0 0.0036" rpy="0.0 0.0 0.0"/>
      <axis xyz="0.0 0.0 -1.0"/>
      <limit lower="-2.0" upper="2.0" effort="100" velocity="100"/>
   </joint>
   <joint type="fixed" name="MCP_spread_4_offset">
      <parent link="MCP_spread_4"/>
      <child link="MCP_spread_motor_4"/>
      <origin xyz="-0.0 -0.0 -0.0" rpy="0.0 0.0 0.0"/>
   </joint>
   <link name="MCP_motor_4">
      <inertial>
         <origin xyz="-0.010500762855210177 0.0279346378824954 -1.6453546218841143e-05" rpy="2.2142146406693315 -1.569753519206229 -0.7069429676930239"/>
         <mass value="0.04035147436542081"/>
         <inertia ixx="1.9492629690810927e-05" iyy="1.6523224440094084e-05" izz="4.743306102438892e-06" ixy="0" ixz="0" iyz="0"/>
      </inertial>
      <visual name="MCP_motor_1">
         <origin xyz="-0.011428398088521013 0.007515922825152364 -4.6353117932732e-05" rpy="1.4447302968900833 -1.5347869918721169 0.12687784385510545"/>
         <geometry>
            <mesh filename="package://converted_MCP_motor_1.stl"/>
         </geometry>
         <material name="white"/>
      </visual>
      <visual name="proximal_1">
         <origin xyz="-0.009990938238875247 0.03915668206144257 -2.086111781582356e-08" rpy="1.3774808759047128 -1.5707963267948966 0.0"/>
         <geometry>
            <mesh filename="package://converted_proximal_1.stl"/>
         </geometry>
         <material name="white"/>
      </visual>
   </link>
   <link name="MCP_4">
      <inertial>
         <origin xyz="0.0 0.0 0.0" rpy="0.0 0.0 0.0"/>
         <mass value="0.001"/>
         <inertia ixx="1e-09" iyy="1e-09" izz="1e-09" ixy="0" ixz="0" iyz="0"/>
      </inertial>
   </link>
   <joint type="revolute" name="MCP_4">
      <parent link="MCP_spread_motor_4"/>
      <child link="MCP_4"/>
      <origin xyz="0.0106 0.0435 -0.0116" rpy="0.0 0.0 0.0"/>
      <axis xyz="-1.0 0.0 0.0"/>
      <limit lower="-2.0" upper="2.0" effort="100" velocity="100"/>
   </joint>
   <joint type="fixed" name="MCP_4_offset">
      <parent link="MCP_4"/>
      <child link="MCP_motor_4"/>
      <origin xyz="-0.0 -0.0 -0.0" rpy="0.0 0.0 0.0"/>
   </joint>
   <link name="PIP_DIP_motor_4">
      <inertial>
         <origin xyz="-0.010914824701867876 0.02295944687359636 -1.8105084342263588e-05" rpy="2.242184262995694 -1.5697116962013469 -0.6928341602075203"/>
         <mass value="0.036640934606382555"/>
         <inertia ixx="1.3325542894551051e-05" iyy="1.0628111048812819e-05" izz="4.3975503665319475e-06" ixy="0" ixz="0" iyz="0"/>
      </inertial>
      <visual name="PIP_DIP_motor_1">
         <origin xyz="-0.011428398389228734 0.007515925594064665 -4.635318888735612e-05" rpy="1.444729319926511 -1.5347868813838343 0.12687878859745186"/>
         <geometry>
            <mesh filename="package://converted_PIP_DIP_motor_1.stl"/>
         </geometry>
         <material name="white"/>
      </visual>
      <visual name="middle_1">
         <origin xyz="-0.01058566312317408 0.032857566598312835 -2.0296691237431386e-10" rpy="2.9223690462600653 -1.5707963267948966 0.0"/>
         <geometry>
            <mesh filename="package://converted_middle_1.stl"/>
         </geometry>
         <material name="white"/>
      </visual>
   </link>
   <link name="PIP_4">
      <inertial>
         <origin xyz="0.0 0.0 0.0" rpy="0.0 0.0 0.0"/>
         <mass value="0.001"/>
         <inertia ixx="1e-09" iyy="1e-09" izz="1e-09" ixy="0" ixz="0" iyz="0"/>
      </inertial>
   </link>
   <joint type="revolute" name="PIP_4">
      <parent link="MCP_motor_4"/>
      <child link="PIP_4"/>
      <origin xyz="0.0 0.059 0.0" rpy="0.0 0.0 0.0"/>
      <axis xyz="-1.0 0.0 0.0"/>
      <limit lower="-2.0" upper="2.0" effort="100" velocity="100"/>
   </joint>
   <joint type="fixed" name="PIP_4_offset">
      <parent link="PIP_4"/>
      <child link="PIP_DIP_motor_4"/>
      <origin xyz="-0.0 -0.0 -0.0" rpy="0.0 0.0 0.0"/>
   </joint>
   <link name="distal_4">
      <inertial>
         <origin xyz="-0.013499999980733406 0.026097314775325453 5.960085598319398e-08" rpy="3.141592653589793 -1.570791449970143 -1.5707963267948966"/>
         <mass value="0.02347525072396419"/>
         <inertia ixx="6.947379008048446e-06" iyy="6.706879032267138e-06" izz="1.6774041387410145e-06" ixy="0" ixz="0" iyz="0"/>
      </inertial>
      <visual name="distal_1">
         <origin xyz="-0.013499999980733406 0.026097314775325453 5.960085598319398e-08" rpy="3.141592653589793 -1.570791449970143 -1.5707963267948966"/>
         <geometry>
            <mesh filename="package://converted_distal_1.stl"/>
         </geometry>
         <material name="white"/>
      </visual>
   </link>
   <link name="DIP_4">
      <inertial>
         <origin xyz="0.0 0.0 0.0" rpy="0.0 0.0 0.0"/>
         <mass value="0.001"/>
         <inertia ixx="1e-09" iyy="1e-09" izz="1e-09" ixy="0" ixz="0" iyz="0"/>
      </inertial>
   </link>
   <joint type="revolute" name="DIP_4">
      <parent link="PIP_DIP_motor_4"/>
      <child link="DIP_4"/>
      <origin xyz="0.0029 0.0505 0.0" rpy="0.0 0.0 0.0"/>
      <axis xyz="1.0 0.0 0.0"/>
      <limit lower="-2.0" upper="2.0" effort="100" velocity="100"/>
   </joint>
   <joint type="fixed" name="DIP_4_offset">
      <parent link="DIP_4"/>
      <child link="distal_4"/>
      <origin xyz="-0.0 -0.0 -0.0" rpy="0.0 0.0 0.0"/>
   </joint>
   <link name="finger_5">
      <inertial>
         <origin xyz="7.486488586106731e-09 -0.008795409811483749 0.00671379288753095" rpy="-5.62659578494751e-15 -1.551063345751673 1.5707963267949023"/>
         <mass value="0.005457218797018834"/>
         <inertia ixx="1.0756152518385642e-06" iyy="7.171729164374252e-07" izz="3.790810947574593e-07" ixy="0" ixz="0" iyz="0"/>
      </inertial>
      <visual name="base_link">
         <origin xyz="6.216408663460327e-08 2.3192417713995757e-06 0.004623478145951719" rpy="3.141592653589793 -1.5707963267948966 0.0"/>
         <geometry>
            <mesh filename="package://converted_base_link.stl"/>
         </geometry>
         <material name="white"/>
      </visual>
   </link>
   <link name="hand2finger_5_fixed">
      <inertial>
         <origin xyz="0.0 0.0 0.0" rpy="0.0 0.0 0.0"/>
         <mass value="0.001"/>
         <inertia ixx="1e-09" iyy="1e-09" izz="1e-09" ixy="0" ixz="0" iyz="0"/>
      </inertial>
   </link>
   <joint type="fixed" name="hand2finger_5_fixed">
      <parent link="hand"/>
      <child link="hand2finger_5_fixed"/>
      <origin xyz="-0.05 -0.11 0.006" rpy="0.0 0.0 3.141592653589793"/>
   </joint>
   <joint type="fixed" name="hand2finger_5_fixed_offset">
      <parent link="hand2finger_5_fixed"/>
      <child link="finger_5"/>
      <origin xyz="-0.0 -0.0 -0.0" rpy="0.0 0.0 0.0"/>
   </joint>
   <link name="MCP_spread_motor_5">
      <inertial>
         <origin xyz="0.0003982548390317494 0.006056317763366704 -0.011559460451449984" rpy="0.19370178971530685 -1.5691490208487457 1.3077529046197847"/>
         <mass value="0.06051675954815346"/>
         <inertia ixx="2.814235433465105e-05" iyy="2.3892426850630282e-05" izz="7.857098025414057e-06" ixy="0" ixz="0" iyz="0"/>
      </inertial>
      <visual name="MCP_spread_motor_1">
         <origin xyz="-4.635344990172431e-05 -0.007515921440695716 -0.011428398130128803" rpy="1.5716895445470493 -0.03571975389681192 -0.004558496347485136"/>
         <geometry>
            <mesh filename="package://converted_MCP_spread_motor_1.stl"/>
         </geometry>
         <material name="white"/>
      </visual>
      <visual name="metacarpal_1">
         <origin xyz="0.0005359663967735601 0.01026013998026553 -0.01160005527813145" rpy="0.9396397687264357 -1.5707910814168278 0.5458940371703993"/>
         <geometry>
            <mesh filename="package://converted_metacarpal_1.stl"/>
         </geometry>
         <material name="white"/>
      </visual>
   </link>
   <link name="MCP_spread_5">
      <inertial>
         <origin xyz="0.0 0.0 0.0" rpy="0.0 0.0 0.0"/>
         <mass value="0.001"/>
         <inertia ixx="1e-09" iyy="1e-09" izz="1e-09" ixy="0" ixz="0" iyz="0"/>
      </inertial>
   </link>
   <joint type="revolute" name="MCP_spread_5">
      <parent link="finger_5"/>
      <child link="MCP_spread_5"/>
      <origin xyz="0.0 0.0 0.0036" rpy="0.0 0.0 0.0"/>
      <axis xyz="0.0 0.0 -1.0"/>
      <limit lower="-2.0" upper="2.0" effort="100" velocity="100"/>
   </joint>
   <joint type="fixed" name="MCP_spread_5_offset">
      <parent link="MCP_spread_5"/>
      <child link="MCP_spread_motor_5"/>
      <origin xyz="-0.0 -0.0 -0.0" rpy="0.0 0.0 0.0"/>
   </joint>
   <link name="MCP_motor_5">
      <inertial>
         <origin xyz="-0.010500762855210177 0.0279346378824954 -1.6453546218841143e-05" rpy="2.2142146406693315 -1.569753519206229 -0.7069429676930239"/>
         <mass value="0.04035147436542081"/>
         <inertia ixx="1.9492629690810927e-05" iyy="1.6523224440094084e-05" izz="4.743306102438892e-06" ixy="0" ixz="0" iyz="0"/>
      </inertial>
      <visual name="MCP_motor_1">
         <origin xyz="-0.011428398088521013 0.007515922825152364 -4.6353117932732e-05" rpy="1.4447302968900833 -1.5347869918721169 0.12687784385510545"/>
         <geometry>
            <mesh filename="package://converted_MCP_motor_1.stl"/>
         </geometry>
         <material name="white"/>
      </visual>
      <visual name="proximal_1">
         <origin xyz="-0.009990938238875247 0.03915668206144257 -2.086111781582356e-08" rpy="1.3774808759047128 -1.5707963267948966 0.0"/>
         <geometry>
            <mesh filename="package://converted_proximal_1.stl"/>
         </geometry>
         <material name="white"/>
      </visual>
   </link>
   <link name="MCP_5">
      <inertial>
         <origin xyz="0.0 0.0 0.0" rpy="0.0 0.0 0.0"/>
         <mass value="0.001"/>
         <inertia ixx="1e-09" iyy="1e-09" izz="1e-09" ixy="0" ixz="0" iyz="0"/>
      </inertial>
   </link>
   <joint type="revolute" name="MCP_5">
      <parent link="MCP_spread_motor_5"/>
      <child link="MCP_5"/>
      <origin xyz="0.0106 0.0435 -0.0116" rpy="0.0 0.0 0.0"/>
      <axis xyz="-1.0 0.0 0.0"/>
      <limit lower="-2.0" upper="2.0" effort="100" velocity="100"/>
   </joint>
   <joint type="fixed" name="MCP_5_offset">
      <parent link="MCP_5"/>
      <child link="MCP_motor_5"/>
      <origin xyz="-0.0 -0.0 -0.0" rpy="0.0 0.0 0.0"/>
   </joint>
   <link name="PIP_DIP_motor_5">
      <inertial>
         <origin xyz="-0.010914824701867876 0.02295944687359636 -1.8105084342263588e-05" rpy="2.242184262995694 -1.5697116962013469 -0.6928341602075203"/>
         <mass value="0.036640934606382555"/>
         <inertia ixx="1.3325542894551051e-05" iyy="1.0628111048812819e-05" izz="4.3975503665319475e-06" ixy="0" ixz="0" iyz="0"/>
      </inertial>
      <visual name="PIP_DIP_motor_1">
         <origin xyz="-0.011428398389228734 0.007515925594064665 -4.635318888735612e-05" rpy="1.444729319926511 -1.5347868813838343 0.12687878859745186"/>
         <geometry>
            <mesh filename="package://converted_PIP_DIP_motor_1.stl"/>
         </geometry>
         <material name="white"/>
      </visual>
      <visual name="middle_1">
         <origin xyz="-0.01058566312317408 0.032857566598312835 -2.0296691237431386e-10" rpy="2.9223690462600653 -1.5707963267948966 0.0"/>
         <geometry>
            <mesh filename="package://converted_middle_1.stl"/>
         </geometry>
         <material name="white"/>
      </visual>
   </link>
   <link name="PIP_5">
      <inertial>
         <origin xyz="0.0 0.0 0.0" rpy="0.0 0.0 0.0"/>
         <mass value="0.001"/>
         <inertia ixx="1e-09" iyy="1e-09" izz="1e-09" ixy="0" ixz="0" iyz="0"/>
      </inertial>
   </link>
   <joint type="revolute" name="PIP_5">
      <parent link="MCP_motor_5"/>
      <child link="PIP_5"/>
      <origin xyz="0.0 0.059 0.0" rpy="0.0 0.0 0.0"/>
      <axis xyz="-1.0 0.0 0.0"/>
      <limit lower="-2.0" upper="2.0" effort="100" velocity="100"/>
   </joint>
   <joint type="fixed" name="PIP_5_offset">
      <parent link="PIP_5"/>
      <child link="PIP_DIP_motor_5"/>
      <origin xyz="-0.0 -0.0 -0.0" rpy="0.0 0.0 0.0"/>
   </joint>
   <link name="distal_5">
      <inertial>
         <origin xyz="-0.013499999980733406 0.026097314775325453 5.960085598319398e-08" rpy="3.141592653589793 -1.570791449970143 -1.5707963267948966"/>
         <mass value="0.02347525072396419"/>
         <inertia ixx="6.947379008048446e-06" iyy="6.706879032267138e-06" izz="1.6774041387410145e-06" ixy="0" ixz="0" iyz="0"/>
      </inertial>
      <visual name="distal_1">
         <origin xyz="-0.013499999980733406 0.026097314775325453 5.960085598319398e-08" rpy="3.141592653589793 -1.570791449970143 -1.5707963267948966"/>
         <geometry>
            <mesh filename="package://converted_distal_1.stl"/>
         </geometry>
         <material name="white"/>
      </visual>
   </link>
   <link name="DIP_5">
      <inertial>
         <origin xyz="0.0 0.0 0.0" rpy="0.0 0.0 0.0"/>
         <mass value="0.001"/>
         <inertia ixx="1e-09" iyy="1e-09" izz="1e-09" ixy="0" ixz="0" iyz="0"/>
      </inertial>
   </link>
   <joint type="revolute" name="DIP_5">
      <parent link="PIP_DIP_motor_5"/>
      <child link="DIP_5"/>
      <origin xyz="0.0029 0.0505 0.0" rpy="0.0 0.0 0.0"/>
      <axis xyz="1.0 0.0 0.0"/>
      <limit lower="-2.0" upper="2.0" effort="100" velocity="100"/>
   </joint>
   <joint type="fixed" name="DIP_5_offset">
      <parent link="DIP_5"/>
      <child link="distal_5"/>
      <origin xyz="-0.0 -0.0 -0.0" rpy="0.0 0.0 0.0"/>
   </joint>
   <link name="finger_6">
      <inertial>
         <origin xyz="7.486488586106731e-09 -0.008795409811483749 0.00671379288753095" rpy="-5.62659578494751e-15 -1.551063345751673 1.5707963267949023"/>
         <mass value="0.005457218797018834"/>
         <inertia ixx="1.0756152518385642e-06" iyy="7.171729164374252e-07" izz="3.790810947574593e-07" ixy="0" ixz="0" iyz="0"/>
      </inertial>
      <visual name="base_link">
         <origin xyz="6.216408663460327e-08 2.3192417713995757e-06 0.004623478145951719" rpy="3.141592653589793 -1.5707963267948966 0.0"/>
         <geometry>
            <mesh filename="package://converted_base_link.stl"/>
         </geometry>
         <material name="white"/>
      </visual>
   </link>
   <link name="hand2finger_6_fixed">
      <inertial>
         <origin xyz="0.0 0.0 0.0" rpy="0.0 0.0 0.0"/>
         <mass value="0.001"/>
         <inertia ixx="1e-09" iyy="1e-09" izz="1e-09" ixy="0" ixz="0" iyz="0"/>
      </inertial>
   </link>
   <joint type="fixed" name="hand2finger_6_fixed">
      <parent link="hand"/>
      <child link="hand2finger_6_fixed"/>
      <origin xyz="0.05 -0.11 0.006" rpy="0.0 0.0 3.141592653589793"/>
   </joint>
   <joint type="fixed" name="hand2finger_6_fixed_offset">
      <parent link="hand2finger_6_fixed"/>
      <child link="finger_6"/>
      <origin xyz="-0.0 -0.0 -0.0" rpy="0.0 0.0 0.0"/>
   </joint>
   <link name="MCP_spread_motor_6">
      <inertial>
         <origin xyz="0.0003982548390317494 0.006056317763366704 -0.011559460451449984" rpy="0.19370178971530685 -1.5691490208487457 1.3077529046197847"/>
         <mass value="0.06051675954815346"/>
         <inertia ixx="2.814235433465105e-05" iyy="2.3892426850630282e-05" izz="7.857098025414057e-06" ixy="0" ixz="0" iyz="0"/>
      </inertial>
      <visual name="MCP_spread_motor_1">
         <origin xyz="-4.635344990172431e-05 -0.007515921440695716 -0.011428398130128803" rpy="1.5716895445470493 -0.03571975389681192 -0.004558496347485136"/>
         <geometry>
            <mesh filename="package://converted_MCP_spread_motor_1.stl"/>
         </geometry>
         <material name="white"/>
      </visual>
      <visual name="metacarpal_1">
         <origin xyz="0.0005359663967735601 0.01026013998026553 -0.01160005527813145" rpy="0.9396397687264357 -1.5707910814168278 0.5458940371703993"/>
         <geometry>
            <mesh filename="package://converted_metacarpal_1.stl"/>
         </geometry>
         <material name="white"/>
      </visual>
   </link>
   <link name="MCP_spread_6">
      <inertial>
         <origin xyz="0.0 0.0 0.0" rpy="0.0 0.0 0.0"/>
         <mass value="0.001"/>
         <inertia ixx="1e-09" iyy="1e-09" izz="1e-09" ixy="0" ixz="0" iyz="0"/>
      </inertial>
   </link>
   <joint type="revolute" name="MCP_spread_6">
      <parent link="finger_6"/>
      <child link="MCP_spread_6"/>
      <origin xyz="0.0 0.0 0.0036" rpy="0.0 0.0 0.0"/>
      <axis xyz="0.0 0.0 -1.0"/>
      <limit lower="-2.0" upper="2.0" effort="100" velocity="100"/>
   </joint>
   <joint type="fixed" name="MCP_spread_6_offset">
      <parent link="MCP_spread_6"/>
      <child link="MCP_spread_motor_6"/>
      <origin xyz="-0.0 -0.0 -0.0" rpy="0.0 0.0 0.0"/>
   </joint>
   <link name="MCP_motor_6">
      <inertial>
         <origin xyz="-0.010500762855210177 0.0279346378824954 -1.6453546218841143e-05" rpy="2.2142146406693315 -1.569753519206229 -0.7069429676930239"/>
         <mass value="0.04035147436542081"/>
         <inertia ixx="1.9492629690810927e-05" iyy="1.6523224440094084e-05" izz="4.743306102438892e-06" ixy="0" ixz="0" iyz="0"/>
      </inertial>
      <visual name="MCP_motor_1">
         <origin xyz="-0.011428398088521013 0.007515922825152364 -4.6353117932732e-05" rpy="1.4447302968900833 -1.5347869918721169 0.12687784385510545"/>
         <geometry>
            <mesh filename="package://converted_MCP_motor_1.stl"/>
         </geometry>
         <material name="white"/>
      </visual>
      <visual name="proximal_1">
         <origin xyz="-0.009990938238875247 0.03915668206144257 -2.086111781582356e-08" rpy="1.3774808759047128 -1.5707963267948966 0.0"/>
         <geometry>
            <mesh filename="package://converted_proximal_1.stl"/>
         </geometry>
         <material name="white"/>
      </visual>
   </link>
   <link name="MCP_6">
      <inertial>
         <origin xyz="0.0 0.0 0.0" rpy="0.0 0.0 0.0"/>
         <mass value="0.001"/>
         <inertia ixx="1e-09" iyy="1e-09" izz="1e-09" ixy="0" ixz="0" iyz="0"/>
      </inertial>
   </link>
   <joint type="revolute" name="MCP_6">
      <parent link="MCP_spread_motor_6"/>
      <child link="MCP_6"/>
      <origin xyz="0.0106 0.0435 -0.0116" rpy="0.0 0.0 0.0"/>
      <axis xyz="-1.0 0.0 0.0"/>
      <limit lower="-2.0" upper="2.0" effort="100" velocity="100"/>
   </joint>
   <joint type="fixed" name="MCP_6_offset">
      <parent link="MCP_6"/>
      <child link="MCP_motor_6"/>
      <origin xyz="-0.0 -0.0 -0.0" rpy="0.0 0.0 0.0"/>
   </joint>
   <link name="PIP_DIP_motor_6">
      <inertial>
         <origin xyz="-0.010914824701867876 0.02295944687359636 -1.8105084342263588e-05" rpy="2.242184262995694 -1.5697116962013469 -0.6928341602075203"/>
         <mass value="0.036640934606382555"/>
         <inertia ixx="1.3325542894551051e-05" iyy="1.0628111048812819e-05" izz="4.3975503665319475e-06" ixy="0" ixz="0" iyz="0"/>
      </inertial>
      <visual name="PIP_DIP_motor_1">
         <origin xyz="-0.011428398389228734 0.007515925594064665 -4.635318888735612e-05" rpy="1.444729319926511 -1.5347868813838343 0.12687878859745186"/>
         <geometry>
            <mesh filename="package://converted_PIP_DIP_motor_1.stl"/>
         </geometry>
         <material name="white"/>
      </visual>
      <visual name="middle_1">
         <origin xyz="-0.01058566312317408 0.032857566598312835 -2.0296691237431386e-10" rpy="2.9223690462600653 -1.5707963267948966 0.0"/>
         <geometry>
            <mesh filename="package://converted_middle_1.stl"/>
         </geometry>
         <material name="white"/>
      </visual>
   </link>
   <link name="PIP_6">
      <inertial>
         <origin xyz="0.0 0.0 0.0" rpy="0.0 0.0 0.0"/>
         <mass value="0.001"/>
         <inertia ixx="1e-09" iyy="1e-09" izz="1e-09" ixy="0" ixz="0" iyz="0"/>
      </inertial>
   </link>
   <joint type="revolute" name="PIP_6">
      <parent link="MCP_motor_6"/>
      <child link="PIP_6"/>
      <origin xyz="0.0 0.059 0.0" rpy="0.0 0.0 0.0"/>
      <axis xyz="-1.0 0.0 0.0"/>
      <limit lower="-2.0" upper="2.0" effort="100" velocity="100"/>
   </joint>
   <joint type="fixed" name="PIP_6_offset">
      <parent link="PIP_6"/>
      <child link="PIP_DIP_motor_6"/>
      <origin xyz="-0.0 -0.0 -0.0" rpy="0.0 0.0 0.0"/>
   </joint>
   <link name="distal_6">
      <inertial>
         <origin xyz="-0.013499999980733406 0.026097314775325453 5.960085598319398e-08" rpy="3.141592653589793 -1.570791449970143 -1.5707963267948966"/>
         <mass value="0.02347525072396419"/>
         <inertia ixx="6.947379008048446e-06" iyy="6.706879032267138e-06" izz="1.6774041387410145e-06" ixy="0" ixz="0" iyz="0"/>
      </inertial>
      <visual name="distal_1">
         <origin xyz="-0.013499999980733406 0.026097314775325453 5.960085598319398e-08" rpy="3.141592653589793 -1.570791449970143 -1.5707963267948966"/>
         <geometry>
            <mesh filename="package://converted_distal_1.stl"/>
         </geometry>
         <material name="white"/>
      </visual>
   </link>
   <link name="DIP_6">
      <inertial>
         <origin xyz="0.0 0.0 0.0" rpy="0.0 0.0 0.0"/>
         <mass value="0.001"/>
         <inertia ixx="1e-09" iyy="1e-09" izz="1e-09" ixy="0" ixz="0" iyz="0"/>
      </inertial>
   </link>
   <joint type="revolute" name="DIP_6">
      <parent link="PIP_DIP_motor_6"/>
      <child link="DIP_6"/>
      <origin xyz="0.0029 0.0505 0.0" rpy="0.0 0.0 0.0"/>
      <axis xyz="1.0 0.0 0.0"/>
      <limit lower="-2.0" upper="2.0" effort="100" velocity="100"/>
   </joint>
   <joint type="fixed" name="DIP_6_offset">
      <parent link="DIP_6"/>
      <child link="distal_6"/>
      <origin xyz="-0.0 -0.0 -0.0" rpy="0.0 0.0 0.0"/>
   </joint>
   <material name="white">
      <color rgba="1 1 1 1"/>
   </material>
</robot>
